<?xml version='1.0'?>
<robot name="quadruped">
    <material name="aluminum"><color rgba="0.8 0.8 0.8 1"/></material>
    <material name="cardboard"><color rgba="0.68 0.5 0.3 1"/></material>
    <material name="plastic"><color rgba="0.1 0.1 0.1 1"/></material>


    

    <link name='chassis_center_link'>
      
      <inertial>
        <origin rpy="0 0 0" xyz="-0.000695 0.064163 -0.000001"/>
	    <mass value="0.098"/>
        <inertia ixx="2.691617e-04" ixy="4.933337e-07" ixz="4.291884e-08" iyy="2.166337e-04" iyz="-7.861271e-09" izz="1.356629e-04"/>
      </inertial>
      

      
	      
	       <visual>
        	<origin rpy="0 0 0" xyz="-0.001137 0.050662 0.000000"/>
	        <geometry><box size="0.045353 0.121569 0.143882"/></geometry>
	        <material name="aluminum"/>
	       </visual>
          
	  
	
        
       
        <collision name='collision'>
          <origin rpy="0 0 0" xyz="-0.001137 0.050662 0.000000"/>
          <laser_retro>0</laser_retro>
          <max_contacts>4</max_contacts>
          <geometry><box size="0.045353 0.121569 0.143882"/></geometry>
        </collision>
        
      

      
    </link>
    
    

    <link name='leg1_left_link'>
      
      <inertial>
        <origin rpy="0 0 0" xyz="0.000192 0.010581 -0.016353"/>
	    <mass value="0.012"/>
        <inertia ixx="7.129164e-06" ixy="-1.083228e-08" ixz="-4.791487e-09" iyy="6.357833e-06" iyz="4.792567e-08" izz="1.558394e-06"/>
      </inertial>
      

      
	      
	  
	
      

      
    </link>
    
    

    <link name='leg4_left_link'>
      
      <inertial>
        <origin rpy="0 0 0" xyz="0.000192 0.010581 -0.016353"/>
	    <mass value="0.012"/>
        <inertia ixx="7.129164e-06" ixy="-1.083228e-08" ixz="-4.791487e-09" iyy="6.357833e-06" iyz="4.792567e-08" izz="1.558394e-06"/>
      </inertial>
      

      
	      
	  
	
      

      
    </link>
    
    

    <link name='leg7_left_link'>
      
      <inertial>
        <origin rpy="0 0 0" xyz="0.000192 0.010581 -0.016353"/>
	    <mass value="0.012"/>
        <inertia ixx="7.129164e-06" ixy="-1.083228e-08" ixz="-4.791487e-09" iyy="6.357833e-06" iyz="4.792567e-08" izz="1.558394e-06"/>
      </inertial>
      

      
	      
	  
	
      

      
    </link>
    
    

    <link name='leg10_left_link'>
      
      <inertial>
        <origin rpy="0 0 0" xyz="0.000192 0.010581 -0.016353"/>
	    <mass value="0.012"/>
        <inertia ixx="7.129164e-06" ixy="-1.083228e-08" ixz="-4.791487e-09" iyy="6.357833e-06" iyz="4.792567e-08" izz="1.558394e-06"/>
      </inertial>
      

      
	      
	  
	
      

      
    </link>
    
    

    <link name='leg12_left_link'>
      
      <inertial>
        <origin rpy="0 0 0" xyz="0.000000 -0.009915 -0.018079"/>
	    <mass value="0.058"/>
        <inertia ixx="1.558414e-05" ixy="-1.729493e-10" ixz="-1.901327e-10" iyy="9.788826e-06" iyz="1.820135e-08" izz="9.495020e-06"/>
      </inertial>
      

      
	      
	       <visual>
        	<origin rpy="0 0 0" xyz="-0.000000 -0.010100 -0.019300"/>
	        <geometry><box size="0.020132 0.040332 0.048600"/></geometry>
	        <material name="plastic"/>
	       </visual>
          
	  
	
      

      
    </link>
    
    

    <link name='leg13_left_link'>
      
      <inertial>
        <origin rpy="0 0 0" xyz="-0.000012 0.005081 0.002498"/>
	    <mass value="0.029"/>
        <inertia ixx="1.642369e-05" ixy="1.345898e-10" ixz="2.694190e-09" iyy="3.420054e-05" iyz="-2.365522e-07" izz="4.988287e-05"/>
      </inertial>
      

      
	      
	       <visual>
        	<origin rpy="0 0 0" xyz="-0.000000 0.000747 0.008500"/>
	        <geometry><box size="0.119989 0.074470 0.017165"/></geometry>
	        <material name="aluminum"/>
	       </visual>
          
	  
	
        
       
        <collision name='collision'>
          <origin rpy="0 0 0" xyz="-0.000000 0.000747 0.008500"/>
          <laser_retro>0</laser_retro>
          <max_contacts>4</max_contacts>
          <geometry><box size="0.119989 0.074470 0.017165"/></geometry>
        </collision>
        
      

      
    </link>
    
    
    
    
    
    
    
    

    <link name='leg1_right_link'>
      
      <inertial>
        <origin rpy="0 0 0" xyz="0.000192 0.010581 -0.016353"/>
	    <mass value="0.012"/>
        <inertia ixx="7.129164e-06" ixy="-1.083228e-08" ixz="-4.791487e-09" iyy="6.357833e-06" iyz="4.792567e-08" izz="1.558394e-06"/>
      </inertial>
      

      
	      
	  
	
      

      
    </link>
    
    

    <link name='leg4_right_link'>
      
      <inertial>
        <origin rpy="0 0 0" xyz="0.000192 0.010581 -0.016353"/>
	    <mass value="0.012"/>
        <inertia ixx="7.129164e-06" ixy="-1.083228e-08" ixz="-4.791487e-09" iyy="6.357833e-06" iyz="4.792567e-08" izz="1.558394e-06"/>
      </inertial>
      

      
	      
	  
	
      

      
    </link>
    
    

    <link name='leg7_right_link'>
      
      <inertial>
        <origin rpy="0 0 0" xyz="0.000192 0.010581 -0.016353"/>
	    <mass value="0.012"/>
        <inertia ixx="7.129164e-06" ixy="-1.083228e-08" ixz="-4.791487e-09" iyy="6.357833e-06" iyz="4.792567e-08" izz="1.558394e-06"/>
      </inertial>
      

      
	      
	  
	
      

      
    </link>
    
    

    <link name='leg10_right_link'>
      
      <inertial>
        <origin rpy="0 0 0" xyz="0.000192 0.010581 -0.016353"/>
	    <mass value="0.012"/>
        <inertia ixx="7.129164e-06" ixy="-1.083228e-08" ixz="-4.791487e-09" iyy="6.357833e-06" iyz="4.792567e-08" izz="1.558394e-06"/>
      </inertial>
      

      
	      
	  
	
      

      
    </link>
    
    

    <link name='leg12_right_link'>
      
      <inertial>
        <origin rpy="0 0 0" xyz="0.000000 -0.009915 -0.018079"/>
	    <mass value="0.058"/>
        <inertia ixx="1.558414e-05" ixy="-1.729493e-10" ixz="-1.901327e-10" iyy="9.788826e-06" iyz="1.820135e-08" izz="9.495020e-06"/>
      </inertial>
      

      
	      
	       <visual>
        	<origin rpy="0 0 0" xyz="-0.000000 -0.010100 -0.019300"/>
	        <geometry><box size="0.020132 0.040332 0.048600"/></geometry>
	        <material name="plastic"/>
	       </visual>
          
	  
	
      

      
    </link>
    
    

    <link name='leg13_right_link'>
      
      <inertial>
        <origin rpy="0 0 0" xyz="-0.000012 0.005081 0.002498"/>
	    <mass value="0.029"/>
        <inertia ixx="1.642369e-05" ixy="1.345898e-10" ixz="2.694190e-09" iyy="3.420054e-05" iyz="-2.365522e-07" izz="4.988287e-05"/>
      </inertial>
      

      
	      
	       <visual>
        	<origin rpy="0 0 0" xyz="-0.000000 0.000747 0.008500"/>
	        <geometry><box size="0.119989 0.074470 0.017165"/></geometry>
	        <material name="aluminum"/>
	       </visual>
          
	  
	
        
       
        <collision name='collision'>
          <origin rpy="0 0 0" xyz="-0.000000 0.000747 0.008500"/>
          <laser_retro>0</laser_retro>
          <max_contacts>4</max_contacts>
          <geometry><box size="0.119989 0.074470 0.017165"/></geometry>
        </collision>
        
      

      
    </link>
    
    
    
    
    
    
    
    

    <link name='arm1_left_link'>
      
      <inertial>
        <origin rpy="0 0 0" xyz="-0.000000 -0.000000 0.001294"/>
	    <mass value="0.002"/>
        <inertia ixx="5.043949e-08" ixy="-3.062436e-14" ixz="-2.642094e-13" iyy="5.043971e-08" iyz="-1.711337e-16" izz="9.700972e-08"/>
      </inertial>
      

      
	      
	  
	
      

      
    </link>
    
    

    <link name='arm3_left_link'>
      
      <inertial>
        <origin rpy="0 0 0" xyz="0.000000 -0.009915 -0.018079"/>
	    <mass value="0.058"/>
        <inertia ixx="1.558414e-05" ixy="-1.729493e-10" ixz="-1.901327e-10" iyy="9.788826e-06" iyz="1.820135e-08" izz="9.495020e-06"/>
      </inertial>
      

      
	      
	       <visual>
        	<origin rpy="0 0 0" xyz="-0.000000 -0.010100 -0.019300"/>
	        <geometry><box size="0.020132 0.040332 0.048600"/></geometry>
	        <material name="plastic"/>
	       </visual>
          
	  
	
      

      
    </link>
    
    

    <link name='arm7_left_link'>
      
      <inertial>
        <origin rpy="0 0 0" xyz="0.000192 0.010581 -0.016353"/>
	    <mass value="0.012"/>
        <inertia ixx="7.129164e-06" ixy="-1.083228e-08" ixz="-4.791487e-09" iyy="6.357833e-06" iyz="4.792567e-08" izz="1.558394e-06"/>
      </inertial>
      

      
	      
	  
	
      

      
    </link>
    
    

    <link name='arm8_left_link'>
      
      <inertial>
        <origin rpy="0 0 0" xyz="0.000000 0.005943 0.019674"/>
	    <mass value="0.01"/>
        <inertia ixx="3.988646e-06" ixy="-3.192255e-12" ixz="2.159262e-09" iyy="4.775230e-06" iyz="-1.564893e-07" izz="1.448142e-06"/>
      </inertial>
      

      
	      
	       <visual>
        	<origin rpy="0 0 0" xyz="0.000000 0.000750 0.030157"/>
	        <geometry><box size="0.040165 0.021665 0.060479"/></geometry>
	        <material name="aluminum"/>
	       </visual>
          
	  
	
        
       
        <collision name='collision'>
          <origin rpy="0 0 0" xyz="0.000000 0.000750 0.030157"/>
          <laser_retro>0</laser_retro>
          <max_contacts>4</max_contacts>
          <geometry><box size="0.040165 0.021665 0.060479"/></geometry>
        </collision>
        
      

      
    </link>
    
    
    
    
    
    

    <link name='arm1_right_link'>
      
      <inertial>
        <origin rpy="0 0 0" xyz="-0.000000 -0.000000 0.001294"/>
	    <mass value="0.002"/>
        <inertia ixx="5.043949e-08" ixy="-3.062436e-14" ixz="-2.642094e-13" iyy="5.043971e-08" iyz="-1.711337e-16" izz="9.700972e-08"/>
      </inertial>
      

      
	      
	  
	
      

      
    </link>
    
    

    <link name='arm3_right_link'>
      
      <inertial>
        <origin rpy="0 0 0" xyz="0.000000 -0.009915 -0.018079"/>
	    <mass value="0.058"/>
        <inertia ixx="1.558414e-05" ixy="-1.729493e-10" ixz="-1.901327e-10" iyy="9.788826e-06" iyz="1.820135e-08" izz="9.495020e-06"/>
      </inertial>
      

      
	      
	       <visual>
        	<origin rpy="0 0 0" xyz="-0.000000 -0.010100 -0.019300"/>
	        <geometry><box size="0.020132 0.040332 0.048600"/></geometry>
	        <material name="plastic"/>
	       </visual>
          
	  
	
      

      
    </link>
    
    

    <link name='arm7_right_link'>
      
      <inertial>
        <origin rpy="0 0 0" xyz="0.000192 0.010581 -0.016353"/>
	    <mass value="0.012"/>
        <inertia ixx="7.129164e-06" ixy="-1.083228e-08" ixz="-4.791487e-09" iyy="6.357833e-06" iyz="4.792567e-08" izz="1.558394e-06"/>
      </inertial>
      

      
	      
	  
	
      

      
    </link>
    
    

    <link name='arm8_right_link'>
      
      <inertial>
        <origin rpy="0 0 0" xyz="0.000000 0.005943 0.019674"/>
	    <mass value="0.01"/>
        <inertia ixx="3.988646e-06" ixy="-3.192255e-12" ixz="2.159262e-09" iyy="4.775230e-06" iyz="-1.564893e-07" izz="1.448142e-06"/>
      </inertial>
      

      
	      
	       <visual>
        	<origin rpy="0 0 0" xyz="0.000000 0.000750 0.030157"/>
	        <geometry><box size="0.040165 0.021665 0.060479"/></geometry>
	        <material name="aluminum"/>
	       </visual>
          
	  
	
        
       
        <collision name='collision'>
          <origin rpy="0 0 0" xyz="0.000000 0.000750 0.030157"/>
          <laser_retro>0</laser_retro>
          <max_contacts>4</max_contacts>
          <geometry><box size="0.040165 0.021665 0.060479"/></geometry>
        </collision>
        
      

      
    </link>
    
    
    
    
    
    

    <link name='head2_center_link'>
      
      <inertial>
        <origin rpy="0 0 0" xyz="0.000000 -0.009915 -0.018079"/>
	    <mass value="0.058"/>
        <inertia ixx="1.558414e-05" ixy="-1.729493e-10" ixz="-1.901327e-10" iyy="9.788826e-06" iyz="1.820135e-08" izz="9.495020e-06"/>
      </inertial>
      

      
	      
	       <visual>
        	<origin rpy="0 0 0" xyz="-0.000000 -0.010100 -0.019300"/>
	        <geometry><box size="0.020132 0.040332 0.048600"/></geometry>
	        <material name="plastic"/>
	       </visual>
          
	  
	
      

      
    </link>
    
    

    <link name='aiy0_center_link'>
      
      <inertial>
        <origin rpy="0 0 0" xyz="-0.000000 0.040452 0.000008"/>
	    <mass value="0.050"/>
        <inertia ixx="3.592418e-05" ixy="2.874626e-13" ixz="7.949236e-14" iyy="3.508779e-05" iyz="2.299236e-09" izz="5.357935e-05"/>
      </inertial>
      

      
	      
	       <visual>
        	<origin rpy="0 0 0" xyz="0.000000 0.043418 0.000000"/>
	        <geometry><box size="0.080330 0.087165 0.046330"/></geometry>
	        <material name="cardboard"/>
	       </visual>
          
	  
	
        
       
        <collision name='collision'>
          <origin rpy="0 0 0" xyz="0.000000 0.043418 0.000000"/>
          <laser_retro>0</laser_retro>
          <max_contacts>4</max_contacts>
          <geometry><box size="0.080330 0.087165 0.046330"/></geometry>
        </collision>
        
      

      
    </link>
    
    
    
    
    



    
      
      
    
      
        <joint name="leg1_left_joint" type="continuous">
 		  <child link="leg1_left_link"/>
 		  <parent link="chassis_center_link"/>
          <origin rpy="0.78539816 -1.57079586 2.35619416" xyz="0.018 0. 0.033"/>
		  <axis xyz="0 0 1"/>
		  <limit effort="1.2748" velocity="2.083"/>
          <joint_properties damping="0.0" friction="0.0"/>  
	    </joint>
      
      
    
      
        <joint name="leg4_left_joint" type="continuous">
 		  <child link="leg4_left_link"/>
 		  <parent link="leg1_left_link"/>
          <origin rpy="-3.26794898e-07 1.57079633e+00 0.00000000e+00" xyz="1.80000000e-02 3.80000033e-02 -2.69999948e-02"/>
		  <axis xyz="0 0 1"/>
		  <limit effort="1.2748" velocity="2.083"/>
          <joint_properties damping="0.0" friction="0.0"/>  
	    </joint>
      
      
    
      
        <joint name="leg7_left_joint" type="continuous">
 		  <child link="leg7_left_link"/>
 		  <parent link="leg4_left_link"/>
          <origin rpy="3.14159200e+00 3.26794897e-07 3.14159233e+00" xyz="1.24182080e-08 6.00000059e-02 -3.49999876e-02"/>
		  <axis xyz="0 0 1"/>
		  <limit effort="1.2748" velocity="2.083"/>
          <joint_properties damping="0.0" friction="0.0"/>  
	    </joint>
      
      
    
      
        <joint name="leg10_left_joint" type="continuous">
 		  <child link="leg10_left_link"/>
 		  <parent link="leg7_left_link"/>
          <origin rpy="1.74886971e-20 3.26794897e-07 -3.26794790e-07" xyz="1.24182041e-08 5.99999941e-02 1.00001242e-03"/>
		  <axis xyz="0 0 1"/>
		  <limit effort="1.2748" velocity="2.083"/>
          <joint_properties damping="0.0" friction="0.0"/>  
	    </joint>
      
      
    
      
        <joint name="leg12_left_joint" type="continuous">
 		  <child link="leg12_left_link"/>
 		  <parent link="leg10_left_link"/>
          <origin rpy="1.57079600e+00 3.26794897e-07 -1.57079698e+00" xyz="-2.00000000e-02 4.40000000e-02 -2.00000000e-02"/>
		  <axis xyz="0 0 1"/>
		  <limit effort="1.2748" velocity="2.083"/>
          <joint_properties damping="0.0" friction="0.0"/>  
	    </joint>
      
      
    
      
        <joint name="leg13_left_joint" type="fixed">
 		  <child link="leg13_left_link"/>
 		  <parent link="leg12_left_link"/>
          <origin rpy="0.0 1.570796 0.0" xyz="-0.016 -0.01 -0.018"/>
		  <axis xyz="0 0 1"/>
		  <limit effort="1.2748" velocity="2.083"/>
          <joint_properties damping="0.0" friction="0.0"/>  
	    </joint>
      
      
    
    
    
    
    
    
    
      
        <joint name="leg1_right_joint" type="continuous">
 		  <child link="leg1_right_link"/>
 		  <parent link="chassis_center_link"/>
          <origin rpy="-0.78539816 1.57079586 2.35619416" xyz="-0.018 0. -0.033"/>
		  <axis xyz="0 0 1"/>
		  <limit effort="1.2748" velocity="2.083"/>
          <joint_properties damping="0.0" friction="0.0"/>  
	    </joint>
      
      
    
      
        <joint name="leg4_right_joint" type="continuous">
 		  <child link="leg4_right_link"/>
 		  <parent link="leg1_right_link"/>
          <origin rpy="3.14159233 -1.57079567 -3.14159265" xyz="-0.01800001 0.038 -0.00700002"/>
		  <axis xyz="0 0 1"/>
		  <limit effort="1.2748" velocity="2.083"/>
          <joint_properties damping="0.0" friction="0.0"/>  
	    </joint>
      
      
    
      
        <joint name="leg7_right_joint" type="continuous">
 		  <child link="leg7_right_link"/>
 		  <parent link="leg4_right_link"/>
          <origin rpy="1.74886971e-20 3.26794897e-07 -3.26794790e-07" xyz="1.24182041e-08 5.99999941e-02 1.00001242e-03"/>
		  <axis xyz="0 0 1"/>
		  <limit effort="1.2748" velocity="2.083"/>
          <joint_properties damping="0.0" friction="0.0"/>  
	    </joint>
      
      
    
      
        <joint name="leg10_right_joint" type="continuous">
 		  <child link="leg10_right_link"/>
 		  <parent link="leg7_right_link"/>
          <origin rpy="1.74886971e-20 3.26794897e-07 -3.26794790e-07" xyz="1.24182041e-08 5.99999941e-02 1.00001242e-03"/>
		  <axis xyz="0 0 1"/>
		  <limit effort="1.2748" velocity="2.083"/>
          <joint_properties damping="0.0" friction="0.0"/>  
	    </joint>
      
      
    
      
        <joint name="leg12_right_joint" type="continuous">
 		  <child link="leg12_right_link"/>
 		  <parent link="leg10_right_link"/>
          <origin rpy="1.57079600e+00 3.26794897e-07 -1.57079698e+00" xyz="-2.00000000e-02 4.40000000e-02 -2.00000000e-02"/>
		  <axis xyz="0 0 1"/>
		  <limit effort="1.2748" velocity="2.083"/>
          <joint_properties damping="0.0" friction="0.0"/>  
	    </joint>
      
      
    
      
        <joint name="leg13_right_joint" type="fixed">
 		  <child link="leg13_right_link"/>
 		  <parent link="leg12_right_link"/>
          <origin rpy="0.0 1.570796 0.0" xyz="-0.016 -0.01 -0.018"/>
		  <axis xyz="0 0 1"/>
		  <limit effort="1.2748" velocity="2.083"/>
          <joint_properties damping="0.0" friction="0.0"/>  
	    </joint>
      
      
    
    
    
    
    
    
    
      
        <joint name="arm1_left_joint" type="continuous">
 		  <child link="arm1_left_link"/>
 		  <parent link="chassis_center_link"/>
          <origin rpy="3.141592e+00 -0.000000e+00 1.570796e+00" xyz="-1.000000e-03 1.020000e-01 7.720000e-02"/>
		  <axis xyz="0 0 1"/>
		  <limit effort="1.2748" velocity="2.083"/>
          <joint_properties damping="0.0" friction="0.0"/>  
	    </joint>
      
      
    
      
        <joint name="arm3_left_joint" type="continuous">
 		  <child link="arm3_left_link"/>
 		  <parent link="arm1_left_link"/>
          <origin rpy="0.78539816 1.57079586 -0.78539816" xyz="0. -0.0169 -0.022"/>
		  <axis xyz="0 0 1"/>
		  <limit effort="1.2748" velocity="2.083"/>
          <joint_properties damping="0.0" friction="0.0"/>  
	    </joint>
      
      
    
      
        <joint name="arm7_left_joint" type="continuous">
 		  <child link="arm7_left_link"/>
 		  <parent link="arm3_left_link"/>
          <origin rpy="-1.30358979e-06 -3.26794900e-07 3.14159233e+00" xyz="-1.24182117e-08 -7.60000176e-02 -3.71182147e-08"/>
		  <axis xyz="0 0 1"/>
		  <limit effort="1.2748" velocity="2.083"/>
          <joint_properties damping="0.0" friction="0.0"/>  
	    </joint>
      
      
    
      
        <joint name="arm8_left_joint" type="fixed">
 		  <child link="arm8_left_link"/>
 		  <parent link="arm7_left_link"/>
          <origin rpy="0.0 1.570796 1.570796" xyz="0.0 0.022 -0.017"/>
		  <axis xyz="0 0 1"/>
		  <limit effort="1.2748" velocity="2.083"/>
          <joint_properties damping="0.0" friction="0.0"/>  
	    </joint>
      
      
    
    
    
    
    
      
        <joint name="arm1_right_joint" type="continuous">
 		  <child link="arm1_right_link"/>
 		  <parent link="chassis_center_link"/>
          <origin rpy="-1.30717959e-06 2.13589809e-13 1.57079665e+00" xyz="-9.99994118e-04 1.02000000e-01 -7.72000000e-02"/>
		  <axis xyz="0 0 1"/>
		  <limit effort="1.2748" velocity="2.083"/>
          <joint_properties damping="0.0" friction="0.0"/>  
	    </joint>
      
      
    
      
        <joint name="arm3_right_joint" type="continuous">
 		  <child link="arm3_right_link"/>
 		  <parent link="arm1_right_link"/>
          <origin rpy="0.78539816 1.57079586 -0.78539816" xyz="0. -0.0169 -0.022"/>
		  <axis xyz="0 0 1"/>
		  <limit effort="1.2748" velocity="2.083"/>
          <joint_properties damping="0.0" friction="0.0"/>  
	    </joint>
      
      
    
      
        <joint name="arm7_right_joint" type="continuous">
 		  <child link="arm7_right_link"/>
 		  <parent link="arm3_right_link"/>
          <origin rpy="-1.30358979e-06 -3.26794900e-07 3.14159233e+00" xyz="-1.24182117e-08 -7.60000176e-02 -3.71182147e-08"/>
		  <axis xyz="0 0 1"/>
		  <limit effort="1.2748" velocity="2.083"/>
          <joint_properties damping="0.0" friction="0.0"/>  
	    </joint>
      
      
    
      
        <joint name="arm8_right_joint" type="fixed">
 		  <child link="arm8_right_link"/>
 		  <parent link="arm7_right_link"/>
          <origin rpy="0.0 1.570796 1.570796" xyz="0.0 0.022 -0.017"/>
		  <axis xyz="0 0 1"/>
		  <limit effort="1.2748" velocity="2.083"/>
          <joint_properties damping="0.0" friction="0.0"/>  
	    </joint>
      
      
    
    
    
    
    
      
        <joint name="head2_center_joint" type="continuous">
 		  <child link="head2_center_link"/>
 		  <parent link="chassis_center_link"/>
          <origin rpy="2.36165719e+00 -1.57079586e+00 -7.90861513e-01" xyz="-9.99994118e-04 1.06000000e-01 -2.90884593e-09"/>
		  <axis xyz="0 0 1"/>
		  <limit effort="1.2748" velocity="2.083"/>
          <joint_properties damping="0.0" friction="0.0"/>  
	    </joint>
      
      
    
      
        <joint name="aiy0_center_joint" type="fixed">
 		  <child link="aiy0_center_link"/>
 		  <parent link="head2_center_link"/>
          <origin rpy="1.570796 3.141592 0.0" xyz="0.0 0.00 -0.039"/>
		  <axis xyz="0 0 1"/>
		  <limit effort="1.2748" velocity="2.083"/>
          <joint_properties damping="0.0" friction="0.0"/>  
	    </joint>
      
      
    
    
    
    

</robot>